Workbook

Sheet GENERAL
AI1: TIENE POSTVENTA | AN1: TIENE POSTVENTA
AI2: NO TIENE POSTVENTA | AN2: NO TIENE POSTVENTA
AI3: POSTVENTA CORREGIDA | AN3: POSTVENTA CORREGIDA
B4: Item | C4: DETALLES | D4: CAPITULO ASIGNADO | E4: CASA #02 | F4: CASA #03 | G4: CASA #04 | H4: CASA #05 | I4: CASA #07 | J4: CASA #11 | K4: CASA #12 | L4: CASA #14 | M4: CASA #15 | N4: CASA #17 | O4: CASA #18 | P4: CASA #19 | Q4: CASA #21 | R4: CASA #22 | S4: CASA #23 | T4: CASA #24 | U4: CASA #25 | V4: CASA #26 | W4: CASA #27 | X4: CASA #28 | Y4: CASA #29 | Z4: CASA #30 | AA4: CASA #31 | AB4: CASA #32 | AC4: CASA #33 | AD4: CASA #35 | AE4: CASA #36 | AF4: CASA #37 | AG4: CASA #38 | AH4: CASA #40 | AI4: CASA #42 | AJ4: CASA #43 | AK4: CASA #44 | AL4: CASA #45 | AM4: CASA #46 | AN4: CASA #47
A6: SALA COMEDOR | B6: 1 | C6: Puerta en madera acceso p/pal | D6: CARPINTERIA EN MADERA | E6: TIENE POSTVENTA | F6: POSTVENTA CORREGIDA | G6: POSTVENTA CORREGIDA | H6: TIENE POSTVENTA | I6: POSTVENTA CORREGIDA | J6: POSTVENTA CORREGIDA | K6: POSTVENTA CORREGIDA | L6: POSTVENTA CORREGIDA | M6: POSTVENTA CORREGIDA | N6: TIENE POSTVENTA | O6: POSTVENTA CORREGIDA | P6: POSTVENTA CORREGIDA | Q6: TIENE POSTVENTA | R6: TIENE POSTVENTA | S6: POSTVENTA CORREGIDA | T6: POSTVENTA CORREGIDA | U6: POSTVENTA CORREGIDA | V6: POSTVENTA CORREGIDA | W6: POSTVENTA CORREGIDA | X6: POSTVENTA CORREGIDA | Y6: POSTVENTA CORREGIDA | Z6: POSTVENTA CORREGIDA | AA6: POSTVENTA CORREGIDA | AB6: POSTVENTA CORREGIDA | AC6: POSTVENTA CORREGIDA | AD6: POSTVENTA CORREGIDA | AE6: TIENE POSTVENTA | AF6: POSTVENTA CORREGIDA | AG6: POSTVENTA CORREGIDA | AH6: TIENE POSTVENTA | AI6: POSTVENTA CORREGIDA | AJ6: POSTVENTA CORREGIDA | AK6: POSTVENTA CORREGIDA | AL6: POSTVENTA CORREGIDA | AM6: POSTVENTA CORREGIDA | AN6: TIENE POSTVENTA
B7: =B6+1 -> 2 | C7: Cerradura Puerta Principal con llaves | D7: CARPINTERIA EN MADERA | E7: TIENE POSTVENTA | F7: POSTVENTA CORREGIDA | G7: POSTVENTA CORREGIDA | H7: TIENE POSTVENTA | I7: POSTVENTA CORREGIDA | J7: POSTVENTA CORREGIDA | K7: POSTVENTA CORREGIDA | L7: POSTVENTA CORREGIDA | M7: POSTVENTA CORREGIDA | N7: POSTVENTA CORREGIDA | O7: POSTVENTA CORREGIDA | P7: POSTVENTA CORREGIDA | Q7: POSTVENTA CORREGIDA | R7: POSTVENTA CORREGIDA | S7: POSTVENTA CORREGIDA | T7: POSTVENTA CORREGIDA | U7: POSTVENTA CORREGIDA | V7: POSTVENTA CORREGIDA | W7: POSTVENTA CORREGIDA | X7: POSTVENTA CORREGIDA | Y7: POSTVENTA CORREGIDA | Z7: POSTVENTA CORREGIDA | AA7: POSTVENTA CORREGIDA | AB7: POSTVENTA CORREGIDA | AC7: POSTVENTA CORREGIDA | AD7: POSTVENTA CORREGIDA | AE7: POSTVENTA CORREGIDA | AF7: POSTVENTA CORREGIDA | AG7: POSTVENTA CORREGIDA | AH7: POSTVENTA CORREGIDA | AI7: POSTVENTA CORREGIDA | AJ7: POSTVENTA CORREGIDA | AK7: POSTVENTA CORREGIDA | AL7: POSTVENTA CORREGIDA | AM7: POSTVENTA CORREGIDA | AN7: POSTVENTA CORREGIDA
B8: 3 | C8: Tope de puerta | D8: CARPINTERIA EN MADERA | E8: TIENE POSTVENTA | F8: POSTVENTA CORREGIDA | G8: POSTVENTA CORREGIDA | H8: TIENE POSTVENTA | I8: POSTVENTA CORREGIDA | J8: POSTVENTA CORREGIDA | K8: POSTVENTA CORREGIDA | L8: POSTVENTA CORREGIDA | M8: POSTVENTA CORREGIDA | N8: POSTVENTA CORREGIDA | O8: POSTVENTA CORREGIDA | P8: POSTVENTA CORREGIDA | Q8: POSTVENTA CORREGIDA | R8: POSTVENTA CORREGIDA | S8: POSTVENTA CORREGIDA | T8: POSTVENTA CORREGIDA | U8: POSTVENTA CORREGIDA | V8: POSTVENTA CORREGIDA | W8: POSTVENTA CORREGIDA | X8: POSTVENTA CORREGIDA | Y8: POSTVENTA CORREGIDA | Z8: POSTVENTA CORREGIDA | AA8: POSTVENTA CORREGIDA | AB8: POSTVENTA CORREGIDA | AC8: POSTVENTA CORREGIDA | AD8: POSTVENTA CORREGIDA | AE8: POSTVENTA CORREGIDA | AF8: POSTVENTA CORREGIDA | AG8: POSTVENTA CORREGIDA | AH8: POSTVENTA CORREGIDA | AI8: POSTVENTA CORREGIDA | AJ8: POSTVENTA CORREGIDA | AK8: POSTVENTA CORREGIDA | AL8: POSTVENTA CORREGIDA | AM8: POSTVENTA CORREGIDA | AN8: POSTVENTA CORREGIDA
B9: 4 | C9: Timbre | D9: REDES ELECTRICAS | E9: TIENE POSTVENTA | F9: POSTVENTA CORREGIDA | G9: POSTVENTA CORREGIDA | H9: TIENE POSTVENTA | I9: POSTVENTA CORREGIDA | J9: POSTVENTA CORREGIDA | K9: POSTVENTA CORREGIDA | L9: POSTVENTA CORREGIDA | M9: POSTVENTA CORREGIDA | N9: POSTVENTA CORREGIDA | O9: POSTVENTA CORREGIDA | P9: POSTVENTA CORREGIDA | Q9: POSTVENTA CORREGIDA | R9: POSTVENTA CORREGIDA | S9: POSTVENTA CORREGIDA | T9: POSTVENTA CORREGIDA | U9: POSTVENTA CORREGIDA | V9: POSTVENTA CORREGIDA | W9: POSTVENTA CORREGIDA | X9: POSTVENTA CORREGIDA | Y9: POSTVENTA CORREGIDA | Z9: POSTVENTA CORREGIDA | AA9: POSTVENTA CORREGIDA | AB9: POSTVENTA CORREGIDA | AC9: POSTVENTA CORREGIDA | AD9: POSTVENTA CORREGIDA | AE9: POSTVENTA CORREGIDA | AF9: POSTVENTA CORREGIDA | AG9: POSTVENTA CORREGIDA | AH9: POSTVENTA CORREGIDA | AI9: POSTVENTA CORREGIDA | AJ9: POSTVENTA CORREGIDA | AK9: POSTVENTA CORREGIDA | AL9: POSTVENTA CORREGIDA | AM9: POSTVENTA CORREGIDA | AN9: POSTVENTA CORREGIDA
B10: =B9+1 -> 5 | C10: Luces | D10: REDES ELECTRICAS | E10: TIENE POSTVENTA | F10: POSTVENTA CORREGIDA | G10: POSTVENTA CORREGIDA | H10: TIENE POSTVENTA | I10: POSTVENTA CORREGIDA | J10: POSTVENTA CORREGIDA | K10: POSTVENTA CORREGIDA | L10: POSTVENTA CORREGIDA | M10: POSTVENTA CORREGIDA | N10: POSTVENTA CORREGIDA | O10: POSTVENTA CORREGIDA | P10: POSTVENTA CORREGIDA | Q10: POSTVENTA CORREGIDA | R10: POSTVENTA CORREGIDA | S10: POSTVENTA CORREGIDA | T10: POSTVENTA CORREGIDA | U10: POSTVENTA CORREGIDA | V10: POSTVENTA CORREGIDA | W10: POSTVENTA CORREGIDA | X10: POSTVENTA CORREGIDA | Y10: POSTVENTA CORREGIDA | Z10: POSTVENTA CORREGIDA | AA10: POSTVENTA CORREGIDA | AB10: POSTVENTA CORREGIDA | AC10: POSTVENTA CORREGIDA | AD10: POSTVENTA CORREGIDA | AE10: POSTVENTA CORREGIDA | AF10: POSTVENTA CORREGIDA | AG10: POSTVENTA CORREGIDA | AH10: POSTVENTA CORREGIDA | AI10: POSTVENTA CORREGIDA | AJ10: POSTVENTA CORREGIDA | AK10: POSTVENTA CORREGIDA | AL10: POSTVENTA CORREGIDA | AM10: POSTVENTA CORREGIDA | AN10: POSTVENTA CORREGIDA
B11: =B10+1 -> 6 | C11: Tomas | D11: REDES ELECTRICAS | E11: TIENE POSTVENTA | F11: POSTVENTA CORREGIDA | G11: POSTVENTA CORREGIDA | H11: TIENE POSTVENTA | I11: POSTVENTA CORREGIDA | J11: POSTVENTA CORREGIDA | K11: POSTVENTA CORREGIDA | L11: POSTVENTA CORREGIDA | M11: POSTVENTA CORREGIDA | N11: POSTVENTA CORREGIDA | O11: POSTVENTA CORREGIDA | P11: POSTVENTA CORREGIDA | Q11: POSTVENTA CORREGIDA | R11: POSTVENTA CORREGIDA | S11: POSTVENTA CORREGIDA | T11: POSTVENTA CORREGIDA | U11: POSTVENTA CORREGIDA | V11: POSTVENTA CORREGIDA | W11: POSTVENTA CORREGIDA | X11: POSTVENTA CORREGIDA | Y11: POSTVENTA CORREGIDA | Z11: POSTVENTA CORREGIDA | AA11: POSTVENTA CORREGIDA | AB11: POSTVENTA CORREGIDA | AC11: POSTVENTA CORREGIDA | AD11: POSTVENTA CORREGIDA | AE11: POSTVENTA CORREGIDA | AF11: POSTVENTA CORREGIDA | AG11: POSTVENTA CORREGIDA | AH11: POSTVENTA CORREGIDA | AI11: POSTVENTA CORREGIDA | AJ11: POSTVENTA CORREGIDA | AK11: POSTVENTA CORREGIDA | AL11: POSTVENTA CORREGIDA | AM11: POSTVENTA CORREGIDA | AN11: POSTVENTA CORREGIDA
B12: =B11+1 -> 7 | C12: Switches | D12: REDES ELECTRICAS | E12: TIENE POSTVENTA | F12: POSTVENTA CORREGIDA | G12: POSTVENTA CORREGIDA | H12: TIENE POSTVENTA | I12: POSTVENTA CORREGIDA | J12: POSTVENTA CORREGIDA | K12: POSTVENTA CORREGIDA | L12: POSTVENTA CORREGIDA | M12: POSTVENTA CORREGIDA | N12: POSTVENTA CORREGIDA | O12: POSTVENTA CORREGIDA | P12: POSTVENTA CORREGIDA | Q12: POSTVENTA CORREGIDA | R12: POSTVENTA CORREGIDA | S12: POSTVENTA CORREGIDA | T12: POSTVENTA CORREGIDA | U12: POSTVENTA CORREGIDA | V12: POSTVENTA CORREGIDA | W12: POSTVENTA CORREGIDA | X12: POSTVENTA CORREGIDA | Y12: POSTVENTA CORREGIDA | Z12: POSTVENTA CORREGIDA | AA12: POSTVENTA CORREGIDA | AB12: POSTVENTA CORREGIDA | AC12: POSTVENTA CORREGIDA | AD12: POSTVENTA CORREGIDA | AE12: POSTVENTA CORREGIDA | AF12: POSTVENTA CORREGIDA | AG12: POSTVENTA CORREGIDA | AH12: POSTVENTA CORREGIDA | AI12: POSTVENTA CORREGIDA | AJ12: POSTVENTA CORREGIDA | AK12: POSTVENTA CORREGIDA | AL12: POSTVENTA CORREGIDA | AM12: POSTVENTA CORREGIDA | AN12: POSTVENTA CORREGIDA
B13: =B12+1 -> 8 | C13: Cableado de Citofono | D13: REDES ELECTRICAS | E13: TIENE POSTVENTA | F13: POSTVENTA CORREGIDA | G13: POSTVENTA CORREGIDA | H13: TIENE POSTVENTA | I13: POSTVENTA CORREGIDA | J13: POSTVENTA CORREGIDA | K13: POSTVENTA CORREGIDA | L13: POSTVENTA CORREGIDA | M13: POSTVENTA CORREGIDA | N13: POSTVENTA CORREGIDA | O13: POSTVENTA CORREGIDA | P13: POSTVENTA CORREGIDA | Q13: POSTVENTA CORREGIDA | R13: POSTVENTA CORREGIDA | S13: POSTVENTA CORREGIDA | T13: POSTVENTA CORREGIDA | U13: POSTVENTA CORREGIDA | V13: POSTVENTA CORREGIDA | W13: POSTVENTA CORREGIDA | X13: POSTVENTA CORREGIDA | Y13: POSTVENTA CORREGIDA | Z13: POSTVENTA CORREGIDA | AA13: POSTVENTA CORREGIDA | AB13: POSTVENTA CORREGIDA | AC13: POSTVENTA CORREGIDA | AD13: POSTVENTA CORREGIDA | AE13: POSTVENTA CORREGIDA | AF13: POSTVENTA CORREGIDA | AG13: POSTVENTA CORREGIDA | AH13: POSTVENTA CORREGIDA | AI13: POSTVENTA CORREGIDA | AJ13: POSTVENTA CORREGIDA | AK13: POSTVENTA CORREGIDA | AL13: POSTVENTA CORREGIDA | AM13: POSTVENTA CORREGIDA | AN13: POSTVENTA CORREGIDA
B14: =B13+1 -> 9 | C14: Punto de Voz y datos/tv | D14: REDES ELECTRICAS | E14: TIENE POSTVENTA | F14: POSTVENTA CORREGIDA | G14: POSTVENTA CORREGIDA | H14: TIENE POSTVENTA | I14: POSTVENTA CORREGIDA | J14: POSTVENTA CORREGIDA | K14: POSTVENTA CORREGIDA | L14: POSTVENTA CORREGIDA | M14: POSTVENTA CORREGIDA | N14: POSTVENTA CORREGIDA | O14: POSTVENTA CORREGIDA | P14: POSTVENTA CORREGIDA | Q14: POSTVENTA CORREGIDA | R14: POSTVENTA CORREGIDA | S14: POSTVENTA CORREGIDA | T14: POSTVENTA CORREGIDA | U14: POSTVENTA CORREGIDA | V14: POSTVENTA CORREGIDA | W14: POSTVENTA CORREGIDA | X14: POSTVENTA CORREGIDA | Y14: POSTVENTA CORREGIDA | Z14: POSTVENTA CORREGIDA | AA14: POSTVENTA CORREGIDA | AB14: POSTVENTA CORREGIDA | AC14: POSTVENTA CORREGIDA | AD14: POSTVENTA CORREGIDA | AE14: POSTVENTA CORREGIDA | AF14: POSTVENTA CORREGIDA | AG14: POSTVENTA CORREGIDA | AH14: POSTVENTA CORREGIDA | AI14: POSTVENTA CORREGIDA | AJ14: POSTVENTA CORREGIDA | AK14: POSTVENTA CORREGIDA | AL14: POSTVENTA CORREGIDA | AM14: POSTVENTA CORREGIDA | AN14: POSTVENTA CORREGIDA
B15: 10 | C15: Tablero Electrico | D15: REDES ELECTRICAS | E15: TIENE POSTVENTA | F15: POSTVENTA CORREGIDA | G15: POSTVENTA CORREGIDA | H15: TIENE POSTVENTA | I15: POSTVENTA CORREGIDA | J15: POSTVENTA CORREGIDA | K15: POSTVENTA CORREGIDA | L15: POSTVENTA CORREGIDA | M15: POSTVENTA CORREGIDA | N15: POSTVENTA CORREGIDA | O15: POSTVENTA CORREGIDA | P15: POSTVENTA CORREGIDA | Q15: POSTVENTA CORREGIDA | R15: POSTVENTA CORREGIDA | S15: POSTVENTA CORREGIDA | T15: POSTVENTA CORREGIDA | U15: POSTVENTA CORREGIDA | V15: POSTVENTA CORREGIDA | W15: POSTVENTA CORREGIDA | X15: POSTVENTA CORREGIDA | Y15: POSTVENTA CORREGIDA | Z15: POSTVENTA CORREGIDA | AA15: POSTVENTA CORREGIDA | AB15: POSTVENTA CORREGIDA | AC15: POSTVENTA CORREGIDA | AD15: POSTVENTA CORREGIDA | AE15: POSTVENTA CORREGIDA | AF15: POSTVENTA CORREGIDA | AG15: POSTVENTA CORREGIDA | AH15: TIENE POSTVENTA | AI15: POSTVENTA CORREGIDA | AJ15: POSTVENTA CORREGIDA | AK15: POSTVENTA CORREGIDA | AL15: POSTVENTA CORREGIDA | AM15: POSTVENTA CORREGIDA | AN15: POSTVENTA CORREGIDA
B16: 11 | C16: Cuñas | D16: REDES ELECTRICAS | E16: TIENE POSTVENTA | F16: POSTVENTA CORREGIDA | G16: POSTVENTA CORREGIDA | H16: TIENE POSTVENTA | I16: POSTVENTA CORREGIDA | J16: POSTVENTA CORREGIDA | K16: POSTVENTA CORREGIDA | L16: POSTVENTA CORREGIDA | M16: POSTVENTA CORREGIDA | N16: POSTVENTA CORREGIDA | O16: POSTVENTA CORREGIDA | P16: POSTVENTA CORREGIDA | Q16: POSTVENTA CORREGIDA | R16: POSTVENTA CORREGIDA | S16: POSTVENTA CORREGIDA | T16: POSTVENTA CORREGIDA | U16: POSTVENTA CORREGIDA | V16: POSTVENTA CORREGIDA | W16: POSTVENTA CORREGIDA | X16: POSTVENTA CORREGIDA | Y16: POSTVENTA CORREGIDA | Z16: POSTVENTA CORREGIDA | AA16: POSTVENTA CORREGIDA | AB16: POSTVENTA CORREGIDA | AC16: POSTVENTA CORREGIDA | AD16: POSTVENTA CORREGIDA | AE16: POSTVENTA CORREGIDA | AF16: POSTVENTA CORREGIDA | AG16: POSTVENTA CORREGIDA | AH16: POSTVENTA CORREGIDA | AI16: POSTVENTA CORREGIDA | AJ16: POSTVENTA CORREGIDA | AK16: POSTVENTA CORREGIDA | AL16: POSTVENTA CORREGIDA | AM16: POSTVENTA CORREGIDA | AN16: POSTVENTA CORREGIDA
B17: 12 | C17: Puertaventana Corrediza | D17: CARPINTERIA METALICA | E17: TIENE POSTVENTA | F17: POSTVENTA CORREGIDA | G17: POSTVENTA CORREGIDA | H17: TIENE POSTVENTA | I17: POSTVENTA CORREGIDA | J17: POSTVENTA CORREGIDA | K17: POSTVENTA CORREGIDA | L17: POSTVENTA CORREGIDA | M17: POSTVENTA CORREGIDA | N17: POSTVENTA CORREGIDA | O17: POSTVENTA CORREGIDA | P17: POSTVENTA CORREGIDA | Q17: POSTVENTA CORREGIDA | R17: POSTVENTA CORREGIDA | S17: POSTVENTA CORREGIDA | T17: POSTVENTA CORREGIDA | U17: POSTVENTA CORREGIDA | V17: POSTVENTA CORREGIDA | W17: POSTVENTA CORREGIDA | X17: POSTVENTA CORREGIDA | Y17: POSTVENTA CORREGIDA | Z17: POSTVENTA CORREGIDA | AA17: POSTVENTA CORREGIDA | AB17: TIENE POSTVENTA | AC17: POSTVENTA CORREGIDA | AD17: POSTVENTA CORREGIDA | AE17: POSTVENTA CORREGIDA | AF17: POSTVENTA CORREGIDA | AG17: POSTVENTA CORREGIDA | AH17: POSTVENTA CORREGIDA | AI17: POSTVENTA CORREGIDA | AJ17: POSTVENTA CORREGIDA | AK17: POSTVENTA CORREGIDA | AL17: POSTVENTA CORREGIDA | AM17: POSTVENTA CORREGIDA | AN17: POSTVENTA CORREGIDA
B18: =B17+1 -> 13 | C18: Ventanas fijas | D18: CARPINTERIA METALICA | E18: TIENE POSTVENTA | F18: POSTVENTA CORREGIDA | G18: POSTVENTA CORREGIDA | H18: TIENE POSTVENTA | I18: POSTVENTA CORREGIDA | J18: POSTVENTA CORREGIDA | K18: POSTVENTA CORREGIDA | L18: POSTVENTA CORREGIDA | M18: POSTVENTA CORREGIDA | N18: POSTVENTA CORREGIDA | O18: POSTVENTA CORREGIDA | P18: POSTVENTA CORREGIDA | Q18: POSTVENTA CORREGIDA | R18: TIENE POSTVENTA | S18: POSTVENTA CORREGIDA | T18: POSTVENTA CORREGIDA | U18: POSTVENTA CORREGIDA | V18: POSTVENTA CORREGIDA | W18: POSTVENTA CORREGIDA | X18: POSTVENTA CORREGIDA | Y18: POSTVENTA CORREGIDA | Z18: POSTVENTA CORREGIDA | AA18: POSTVENTA CORREGIDA | AB18: POSTVENTA CORREGIDA | AC18: POSTVENTA CORREGIDA | AD18: POSTVENTA CORREGIDA | AE18: POSTVENTA CORREGIDA | AF18: POSTVENTA CORREGIDA | AG18: POSTVENTA CORREGIDA | AH18: POSTVENTA CORREGIDA | AI18: POSTVENTA CORREGIDA | AJ18: POSTVENTA CORREGIDA | AK18: POSTVENTA CORREGIDA | AL18: POSTVENTA CORREGIDA | AM18: POSTVENTA CORREGIDA | AN18: POSTVENTA CORREGIDA
B19: =B18+1 -> 14 | C19: Redes Aire Acondicionado | D19: REDES A.A. | E19: TIENE POSTVENTA | F19: POSTVENTA CORREGIDA | G19: POSTVENTA CORREGIDA | H19: TIENE POSTVENTA | I19: POSTVENTA CORREGIDA | J19: POSTVENTA CORREGIDA | K19: POSTVENTA CORREGIDA | L19: POSTVENTA CORREGIDA | M19: POSTVENTA CORREGIDA | N19: POSTVENTA CORREGIDA | O19: POSTVENTA CORREGIDA | P19: POSTVENTA CORREGIDA | Q19: POSTVENTA CORREGIDA | R19: POSTVENTA CORREGIDA | S19: POSTVENTA CORREGIDA | T19: POSTVENTA CORREGIDA | U19: POSTVENTA CORREGIDA | V19: POSTVENTA CORREGIDA | W19: POSTVENTA CORREGIDA | X19: POSTVENTA CORREGIDA | Y19: POSTVENTA CORREGIDA | Z19: POSTVENTA CORREGIDA | AA19: POSTVENTA CORREGIDA | AB19: POSTVENTA CORREGIDA | AC19: POSTVENTA CORREGIDA | AD19: POSTVENTA CORREGIDA | AE19: POSTVENTA CORREGIDA | AF19: POSTVENTA CORREGIDA | AG19: POSTVENTA CORREGIDA | AH19: POSTVENTA CORREGIDA | AI19: POSTVENTA CORREGIDA | AJ19: POSTVENTA CORREGIDA | AK19: POSTVENTA CORREGIDA | AL19: POSTVENTA CORREGIDA | AM19: POSTVENTA CORREGIDA | AN19: POSTVENTA CORREGIDA
B20: 15 | C20: Drenaje AA | D20: REDES HS | E20: TIENE POSTVENTA | F20: POSTVENTA CORREGIDA | G20: POSTVENTA CORREGIDA | H20: TIENE POSTVENTA | I20: POSTVENTA CORREGIDA | J20: POSTVENTA CORREGIDA | K20: POSTVENTA CORREGIDA | L20: POSTVENTA CORREGIDA | M20: POSTVENTA CORREGIDA | N20: POSTVENTA CORREGIDA | O20: POSTVENTA CORREGIDA | P20: POSTVENTA CORREGIDA | Q20: POSTVENTA CORREGIDA | R20: POSTVENTA CORREGIDA | S20: POSTVENTA CORREGIDA | T20: POSTVENTA CORREGIDA | U20: POSTVENTA CORREGIDA | V20: POSTVENTA CORREGIDA | W20: POSTVENTA CORREGIDA | X20: POSTVENTA CORREGIDA | Y20: POSTVENTA CORREGIDA | Z20: POSTVENTA CORREGIDA | AA20: POSTVENTA CORREGIDA | AB20: POSTVENTA CORREGIDA | AC20: POSTVENTA CORREGIDA | AD20: POSTVENTA CORREGIDA | AE20: POSTVENTA CORREGIDA | AF20: POSTVENTA CORREGIDA | AG20: POSTVENTA CORREGIDA | AH20: POSTVENTA CORREGIDA | AI20: POSTVENTA CORREGIDA | AJ20: POSTVENTA CORREGIDA | AK20: POSTVENTA CORREGIDA | AL20: POSTVENTA CORREGIDA | AM20: POSTVENTA CORREGIDA | AN20: POSTVENTA CORREGIDA
B21: 17 | C21: Piso | D21: PISOS Y ENCHAPES | E21: TIENE POSTVENTA | F21: POSTVENTA CORREGIDA | G21: POSTVENTA CORREGIDA | H21: TIENE POSTVENTA | I21: POSTVENTA CORREGIDA | J21: POSTVENTA CORREGIDA | K21: POSTVENTA CORREGIDA | L21: TIENE POSTVENTA | M21: POSTVENTA CORREGIDA | N21: POSTVENTA CORREGIDA | O21: TIENE POSTVENTA | P21: POSTVENTA CORREGIDA | Q21: TIENE POSTVENTA | R21: POSTVENTA CORREGIDA | S21: POSTVENTA CORREGIDA | T21: POSTVENTA CORREGIDA | U21: POSTVENTA CORREGIDA | V21: POSTVENTA CORREGIDA | W21: TIENE POSTVENTA | X21: POSTVENTA CORREGIDA | Y21: POSTVENTA CORREGIDA | Z21: POSTVENTA CORREGIDA | AA21: POSTVENTA CORREGIDA | AB21: TIENE POSTVENTA | AC21: POSTVENTA CORREGIDA | AD21: POSTVENTA CORREGIDA | AE21: TIENE POSTVENTA | AF21: POSTVENTA CORREGIDA | AG21: POSTVENTA CORREGIDA | AH21: TIENE POSTVENTA | AI21: POSTVENTA CORREGIDA | AJ21: TIENE POSTVENTA | AK21: POSTVENTA CORREGIDA | AL21: POSTVENTA CORREGIDA | AM21: POSTVENTA CORREGIDA | AN21: TIENE POSTVENTA
B22: 18 | C22: Guardaescobas | D22: PISOS Y ENCHAPES | E22: TIENE POSTVENTA | F22: POSTVENTA CORREGIDA | G22: POSTVENTA CORREGIDA | H22: TIENE POSTVENTA | I22: POSTVENTA CORREGIDA | J22: POSTVENTA CORREGIDA | K22: POSTVENTA CORREGIDA | L22: POSTVENTA CORREGIDA | M22: POSTVENTA CORREGIDA | N22: POSTVENTA CORREGIDA | O22: POSTVENTA CORREGIDA | P22: POSTVENTA CORREGIDA | Q22: POSTVENTA CORREGIDA | R22: POSTVENTA CORREGIDA | S22: POSTVENTA CORREGIDA | T22: POSTVENTA CORREGIDA | U22: POSTVENTA CORREGIDA | V22: POSTVENTA CORREGIDA | W22: POSTVENTA CORREGIDA | X22: POSTVENTA CORREGIDA | Y22: POSTVENTA CORREGIDA | Z22: POSTVENTA CORREGIDA | AA22: POSTVENTA CORREGIDA | AB22: POSTVENTA CORREGIDA | AC22: POSTVENTA CORREGIDA | AD22: POSTVENTA CORREGIDA | AE22: POSTVENTA CORREGIDA | AF22: POSTVENTA CORREGIDA | AG22: POSTVENTA CORREGIDA | AH22: TIENE POSTVENTA | AI22: POSTVENTA CORREGIDA | AJ22: POSTVENTA CORREGIDA | AK22: POSTVENTA CORREGIDA | AL22: POSTVENTA CORREGIDA | AM22: POSTVENTA CORREGIDA | AN22: POSTVENTA CORREGIDA
B23: 19 | C23: Cielorasos | D23: CIELO RASO | E23: TIENE POSTVENTA | F23: POSTVENTA CORREGIDA | G23: POSTVENTA CORREGIDA | H23: TIENE POSTVENTA | I23: POSTVENTA CORREGIDA | J23: POSTVENTA CORREGIDA | K23: POSTVENTA CORREGIDA | L23: POSTVENTA CORREGIDA | M23: POSTVENTA CORREGIDA | N23: POSTVENTA CORREGIDA | O23: POSTVENTA CORREGIDA | P23: POSTVENTA CORREGIDA | Q23: TIENE POSTVENTA | R23: POSTVENTA CORREGIDA | S23: POSTVENTA CORREGIDA | T23: POSTVENTA CORREGIDA | U23: POSTVENTA CORREGIDA | V23: TIENE POSTVENTA | W23: POSTVENTA CORREGIDA | X23: POSTVENTA CORREGIDA | Y23: TIENE POSTVENTA | Z23: POSTVENTA CORREGIDA | AA23: POSTVENTA CORREGIDA | AB23: POSTVENTA CORREGIDA | AC23: POSTVENTA CORREGIDA | AD23: POSTVENTA CORREGIDA | AE23: POSTVENTA CORREGIDA | AF23: POSTVENTA CORREGIDA | AG23: POSTVENTA CORREGIDA | AH23: TIENE POSTVENTA | AI23: POSTVENTA CORREGIDA | AJ23: POSTVENTA CORREGIDA | AK23: POSTVENTA CORREGIDA | AL23: POSTVENTA CORREGIDA | AM23: POSTVENTA CORREGIDA | AN23: POSTVENTA CORREGIDA
B24: 21 | C24: Muros | D24: ESTUCOS Y PINTURA | E24: TIENE POSTVENTA | F24: POSTVENTA CORREGIDA | G24: POSTVENTA CORREGIDA | H24: TIENE POSTVENTA | I24: POSTVENTA CORREGIDA | J24: POSTVENTA CORREGIDA | K24: POSTVENTA CORREGIDA | L24: TIENE POSTVENTA | M24: POSTVENTA CORREGIDA | N24: POSTVENTA CORREGIDA | O24: POSTVENTA CORREGIDA | P24: POSTVENTA CORREGIDA | Q24: TIENE POSTVENTA | R24: POSTVENTA CORREGIDA | S24: POSTVENTA CORREGIDA | T24: TIENE POSTVENTA | U24: TIENE POSTVENTA | V24: TIENE POSTVENTA | W24: TIENE POSTVENTA | X24: TIENE POSTVENTA | Y24: TIENE POSTVENTA | Z24: POSTVENTA CORREGIDA | AA24: POSTVENTA CORREGIDA | AB24: POSTVENTA CORREGIDA | AC24: POSTVENTA CORREGIDA | AD24: POSTVENTA CORREGIDA | AE24: POSTVENTA CORREGIDA | AF24: TIENE POSTVENTA | AG24: POSTVENTA CORREGIDA | AH24: POSTVENTA CORREGIDA | AI24: TIENE POSTVENTA | AJ24: POSTVENTA CORREGIDA | AK24: TIENE POSTVENTA | AL24: POSTVENTA CORREGIDA | AM24: POSTVENTA CORREGIDA | AN24: POSTVENTA CORREGIDA
A25: COCINA | B25: =+B24+1 -> 22 | C25: Luces | D25: REDES ELECTRICAS | E25: TIENE POSTVENTA | F25: POSTVENTA CORREGIDA | G25: POSTVENTA CORREGIDA | H25: TIENE POSTVENTA | I25: POSTVENTA CORREGIDA | J25: POSTVENTA CORREGIDA | K25: POSTVENTA CORREGIDA | L25: POSTVENTA CORREGIDA | M25: POSTVENTA CORREGIDA | N25: POSTVENTA CORREGIDA | O25: POSTVENTA CORREGIDA | P25: POSTVENTA CORREGIDA | Q25: POSTVENTA CORREGIDA | R25: POSTVENTA CORREGIDA | S25: POSTVENTA CORREGIDA | T25: POSTVENTA CORREGIDA | U25: POSTVENTA CORREGIDA | V25: POSTVENTA CORREGIDA | W25: POSTVENTA CORREGIDA | X25: POSTVENTA CORREGIDA | Y25: POSTVENTA CORREGIDA | Z25: POSTVENTA CORREGIDA | AA25: POSTVENTA CORREGIDA | AB25: POSTVENTA CORREGIDA | AC25: POSTVENTA CORREGIDA | AD25: POSTVENTA CORREGIDA | AE25: POSTVENTA CORREGIDA | AF25: POSTVENTA CORREGIDA | AG25: POSTVENTA CORREGIDA | AH25: POSTVENTA CORREGIDA | AI25: POSTVENTA CORREGIDA | AJ25: POSTVENTA CORREGIDA | AK25: POSTVENTA CORREGIDA | AL25: POSTVENTA CORREGIDA | AM25: POSTVENTA CORREGIDA | AN25: POSTVENTA CORREGIDA
B26: =+B25+1 -> 23 | C26: Switches | D26: REDES ELECTRICAS | E26: TIENE POSTVENTA | F26: POSTVENTA CORREGIDA | G26: POSTVENTA CORREGIDA | H26: TIENE POSTVENTA | I26: POSTVENTA CORREGIDA | J26: POSTVENTA CORREGIDA | K26: POSTVENTA CORREGIDA | L26: POSTVENTA CORREGIDA | M26: POSTVENTA CORREGIDA | N26: POSTVENTA CORREGIDA | O26: POSTVENTA CORREGIDA | P26: POSTVENTA CORREGIDA | Q26: POSTVENTA CORREGIDA | R26: POSTVENTA CORREGIDA | S26: POSTVENTA CORREGIDA | T26: POSTVENTA CORREGIDA | U26: POSTVENTA CORREGIDA | V26: POSTVENTA CORREGIDA | W26: POSTVENTA CORREGIDA | X26: POSTVENTA CORREGIDA | Y26: POSTVENTA CORREGIDA | Z26: POSTVENTA CORREGIDA | AA26: POSTVENTA CORREGIDA | AB26: POSTVENTA CORREGIDA | AC26: POSTVENTA CORREGIDA | AD26: POSTVENTA CORREGIDA | AE26: POSTVENTA CORREGIDA | AF26: POSTVENTA CORREGIDA | AG26: POSTVENTA CORREGIDA | AH26: POSTVENTA CORREGIDA | AI26: POSTVENTA CORREGIDA | AJ26: POSTVENTA CORREGIDA | AK26: POSTVENTA CORREGIDA | AL26: POSTVENTA CORREGIDA | AM26: POSTVENTA CORREGIDA | AN26: POSTVENTA CORREGIDA
B27: =+B26+1 -> 24 | C27: Extractor | D27: REDES ELECTRICAS | E27: TIENE POSTVENTA | F27: POSTVENTA CORREGIDA | G27: POSTVENTA CORREGIDA | H27: TIENE POSTVENTA | I27: POSTVENTA CORREGIDA | J27: POSTVENTA CORREGIDA | K27: POSTVENTA CORREGIDA | L27: POSTVENTA CORREGIDA | M27: POSTVENTA CORREGIDA | N27: POSTVENTA CORREGIDA | O27: POSTVENTA CORREGIDA | P27: POSTVENTA CORREGIDA | Q27: POSTVENTA CORREGIDA | R27: POSTVENTA CORREGIDA | S27: POSTVENTA CORREGIDA | T27: POSTVENTA CORREGIDA | U27: POSTVENTA CORREGIDA | V27: POSTVENTA CORREGIDA | W27: POSTVENTA CORREGIDA | X27: POSTVENTA CORREGIDA | Y27: POSTVENTA CORREGIDA | Z27: POSTVENTA CORREGIDA | AA27: POSTVENTA CORREGIDA | AB27: POSTVENTA CORREGIDA | AC27: POSTVENTA CORREGIDA | AD27: POSTVENTA CORREGIDA | AE27: POSTVENTA CORREGIDA | AF27: POSTVENTA CORREGIDA | AG27: POSTVENTA CORREGIDA | AH27: POSTVENTA CORREGIDA | AI27: POSTVENTA CORREGIDA | AJ27: POSTVENTA CORREGIDA | AK27: POSTVENTA CORREGIDA | AL27: POSTVENTA CORREGIDA | AM27: POSTVENTA CORREGIDA | AN27: POSTVENTA CORREGIDA
B28: =+B27+1 -> 25 | C28: Griferias | D28: APARATOS Y MESONES | E28: TIENE POSTVENTA | F28: POSTVENTA CORREGIDA | G28: POSTVENTA CORREGIDA | H28: TIENE POSTVENTA | I28: POSTVENTA CORREGIDA | J28: POSTVENTA CORREGIDA | K28: POSTVENTA CORREGIDA | L28: POSTVENTA CORREGIDA | M28: POSTVENTA CORREGIDA | N28: POSTVENTA CORREGIDA | O28: POSTVENTA CORREGIDA | P28: POSTVENTA CORREGIDA | Q28: POSTVENTA CORREGIDA | R28: POSTVENTA CORREGIDA | S28: POSTVENTA CORREGIDA | T28: POSTVENTA CORREGIDA | U28: POSTVENTA CORREGIDA | V28: POSTVENTA CORREGIDA | W28: POSTVENTA CORREGIDA | X28: POSTVENTA CORREGIDA | Y28: POSTVENTA CORREGIDA | Z28: POSTVENTA CORREGIDA | AA28: POSTVENTA CORREGIDA | AB28: POSTVENTA CORREGIDA | AC28: POSTVENTA CORREGIDA | AD28: POSTVENTA CORREGIDA | AE28: POSTVENTA CORREGIDA | AF28: POSTVENTA CORREGIDA | AG28: POSTVENTA CORREGIDA | AH28: POSTVENTA CORREGIDA | AI28: POSTVENTA CORREGIDA | AJ28: POSTVENTA CORREGIDA | AK28: POSTVENTA CORREGIDA | AL28: POSTVENTA CORREGIDA | AM28: TIENE POSTVENTA | AN28: POSTVENTA CORREGIDA
B29: =+B28+1 -> 26 | C29: Lavaplatos | D29: APARATOS Y MESONES | E29: TIENE POSTVENTA | F29: POSTVENTA CORREGIDA | G29: POSTVENTA CORREGIDA | H29: TIENE POSTVENTA | I29: POSTVENTA CORREGIDA | J29: POSTVENTA CORREGIDA | K29: POSTVENTA CORREGIDA | L29: POSTVENTA CORREGIDA | M29: POSTVENTA CORREGIDA | N29: POSTVENTA CORREGIDA | O29: POSTVENTA CORREGIDA | P29: POSTVENTA CORREGIDA | Q29: POSTVENTA CORREGIDA | R29: POSTVENTA CORREGIDA | S29: POSTVENTA CORREGIDA | T29: POSTVENTA CORREGIDA | U29: POSTVENTA CORREGIDA | V29: POSTVENTA CORREGIDA | W29: POSTVENTA CORREGIDA | X29: POSTVENTA CORREGIDA | Y29: POSTVENTA CORREGIDA | Z29: POSTVENTA CORREGIDA | AA29: POSTVENTA CORREGIDA | AB29: POSTVENTA CORREGIDA | AC29: POSTVENTA CORREGIDA | AD29: POSTVENTA CORREGIDA | AE29: POSTVENTA CORREGIDA | AF29: POSTVENTA CORREGIDA | AG29: POSTVENTA CORREGIDA | AH29: TIENE POSTVENTA | AI29: POSTVENTA CORREGIDA | AJ29: POSTVENTA CORREGIDA | AK29: POSTVENTA CORREGIDA | AL29: POSTVENTA CORREGIDA | AM29: POSTVENTA CORREGIDA | AN29: TIENE POSTVENTA
B30: =+B29+1 -> 27 | C30: mesón | D30: APARATOS Y MESONES | E30: TIENE POSTVENTA | F30: POSTVENTA CORREGIDA | G30: POSTVENTA CORREGIDA | H30: TIENE POSTVENTA | I30: POSTVENTA CORREGIDA | J30: POSTVENTA CORREGIDA | K30: POSTVENTA CORREGIDA | L30: POSTVENTA CORREGIDA | M30: POSTVENTA CORREGIDA | N30: POSTVENTA CORREGIDA | O30: POSTVENTA CORREGIDA | P30: POSTVENTA CORREGIDA | Q30: POSTVENTA CORREGIDA | R30: POSTVENTA CORREGIDA | S30: POSTVENTA CORREGIDA | T30: POSTVENTA CORREGIDA | U30: POSTVENTA CORREGIDA | V30: POSTVENTA CORREGIDA | W30: POSTVENTA CORREGIDA | X30: POSTVENTA CORREGIDA | Y30: POSTVENTA CORREGIDA | Z30: POSTVENTA CORREGIDA | AA30: POSTVENTA CORREGIDA | AB30: POSTVENTA CORREGIDA | AC30: POSTVENTA CORREGIDA | AD30: POSTVENTA CORREGIDA | AE30: POSTVENTA CORREGIDA | AF30: POSTVENTA CORREGIDA | AG30: POSTVENTA CORREGIDA | AH30: POSTVENTA CORREGIDA | AI30: POSTVENTA CORREGIDA | AJ30: POSTVENTA CORREGIDA | AK30: POSTVENTA CORREGIDA | AL30: POSTVENTA CORREGIDA | AM30: POSTVENTA CORREGIDA | AN30: POSTVENTA CORREGIDA
B31: =+B30+1 -> 28 | C31: salpicadero | D31: APARATOS Y MESONES | E31: TIENE POSTVENTA | F31: POSTVENTA CORREGIDA | G31: POSTVENTA CORREGIDA | H31: TIENE POSTVENTA | I31: POSTVENTA CORREGIDA | J31: POSTVENTA CORREGIDA | K31: POSTVENTA CORREGIDA | L31: POSTVENTA CORREGIDA | M31: POSTVENTA CORREGIDA | N31: POSTVENTA CORREGIDA | O31: POSTVENTA CORREGIDA | P31: POSTVENTA CORREGIDA | Q31: POSTVENTA CORREGIDA | R31: POSTVENTA CORREGIDA | S31: POSTVENTA CORREGIDA | T31: POSTVENTA CORREGIDA | U31: POSTVENTA CORREGIDA | V31: POSTVENTA CORREGIDA | W31: TIENE POSTVENTA | X31: POSTVENTA CORREGIDA | Y31: POSTVENTA CORREGIDA | Z31: POSTVENTA CORREGIDA | AA31: POSTVENTA CORREGIDA | AB31: POSTVENTA CORREGIDA | AC31: POSTVENTA CORREGIDA | AD31: POSTVENTA CORREGIDA | AE31: POSTVENTA CORREGIDA | AF31: POSTVENTA CORREGIDA | AG31: POSTVENTA CORREGIDA | AH31: POSTVENTA CORREGIDA | AI31: POSTVENTA CORREGIDA | AJ31: POSTVENTA CORREGIDA | AK31: POSTVENTA CORREGIDA | AL31: POSTVENTA CORREGIDA | AM31: POSTVENTA CORREGIDA | AN31: POSTVENTA CORREGIDA
B32: =+B31+1 -> 29 | C32: mueble inferior | D32: CARPINTERIA DE MADERA | E32: TIENE POSTVENTA | F32: POSTVENTA CORREGIDA | G32: POSTVENTA CORREGIDA | H32: TIENE POSTVENTA | I32: POSTVENTA CORREGIDA | J32: POSTVENTA CORREGIDA | K32: POSTVENTA CORREGIDA | L32: POSTVENTA CORREGIDA | M32: POSTVENTA CORREGIDA | N32: POSTVENTA CORREGIDA | O32: TIENE POSTVENTA | P32: POSTVENTA CORREGIDA | Q32: POSTVENTA CORREGIDA | R32: POSTVENTA CORREGIDA | S32: POSTVENTA CORREGIDA | T32: POSTVENTA CORREGIDA | U32: POSTVENTA CORREGIDA | V32: POSTVENTA CORREGIDA | W32: POSTVENTA CORREGIDA | X32: POSTVENTA CORREGIDA | Y32: POSTVENTA CORREGIDA | Z32: POSTVENTA CORREGIDA | AA32: POSTVENTA CORREGIDA | AB32: TIENE POSTVENTA | AC32: POSTVENTA CORREGIDA | AD32: POSTVENTA CORREGIDA | AE32: POSTVENTA CORREGIDA | AF32: POSTVENTA CORREGIDA | AG32: POSTVENTA CORREGIDA | AH32: TIENE POSTVENTA | AI32: POSTVENTA CORREGIDA | AJ32: TIENE POSTVENTA | AK32: POSTVENTA CORREGIDA | AL32: POSTVENTA CORREGIDA | AM32: POSTVENTA CORREGIDA | AN32: POSTVENTA CORREGIDA
B33: =+B32+1 -> 30 | C33: mueble superior | E33: TIENE POSTVENTA | F33: POSTVENTA CORREGIDA | G33: POSTVENTA CORREGIDA | H33: TIENE POSTVENTA | I33: POSTVENTA CORREGIDA | J33: POSTVENTA CORREGIDA | K33: POSTVENTA CORREGIDA | L33: POSTVENTA CORREGIDA | M33: POSTVENTA CORREGIDA | N33: POSTVENTA CORREGIDA | O33: TIENE POSTVENTA | P33: POSTVENTA CORREGIDA | Q33: TIENE POSTVENTA | R33: POSTVENTA CORREGIDA | S33: POSTVENTA CORREGIDA | T33: POSTVENTA CORREGIDA | U33: POSTVENTA CORREGIDA | V33: POSTVENTA CORREGIDA | W33: TIENE POSTVENTA | X33: POSTVENTA CORREGIDA | Y33: POSTVENTA CORREGIDA | Z33: POSTVENTA CORREGIDA | AA33: POSTVENTA CORREGIDA | AB33: POSTVENTA CORREGIDA | AC33: POSTVENTA CORREGIDA | AD33: POSTVENTA CORREGIDA | AE33: POSTVENTA CORREGIDA | AF33: POSTVENTA CORREGIDA | AG33: POSTVENTA CORREGIDA | AH33: POSTVENTA CORREGIDA | AI33: POSTVENTA CORREGIDA | AJ33: POSTVENTA CORREGIDA | AK33: POSTVENTA CORREGIDA | AL33: POSTVENTA CORREGIDA | AM33: POSTVENTA CORREGIDA | AN33: POSTVENTA CORREGIDA
B34: 38 | C34: Enchape | E34: TIENE POSTVENTA | F34: POSTVENTA CORREGIDA | G34: POSTVENTA CORREGIDA | H34: TIENE POSTVENTA | I34: POSTVENTA CORREGIDA | J34: POSTVENTA CORREGIDA | K34: POSTVENTA CORREGIDA | L34: POSTVENTA CORREGIDA | M34: POSTVENTA CORREGIDA | N34: POSTVENTA CORREGIDA | O34: POSTVENTA CORREGIDA | P34: POSTVENTA CORREGIDA | Q34: POSTVENTA CORREGIDA | R34: POSTVENTA CORREGIDA | S34: POSTVENTA CORREGIDA | T34: POSTVENTA CORREGIDA | U34: POSTVENTA CORREGIDA | V34: POSTVENTA CORREGIDA | W34: POSTVENTA CORREGIDA | X34: POSTVENTA CORREGIDA | Y34: POSTVENTA CORREGIDA | Z34: POSTVENTA CORREGIDA | AA34: POSTVENTA CORREGIDA | AB34: POSTVENTA CORREGIDA | AC34: POSTVENTA CORREGIDA | AD34: POSTVENTA CORREGIDA | AE34: POSTVENTA CORREGIDA | AF34: POSTVENTA CORREGIDA | AG34: POSTVENTA CORREGIDA | AH34: POSTVENTA CORREGIDA | AI34: POSTVENTA CORREGIDA | AJ34: POSTVENTA CORREGIDA | AK34: POSTVENTA CORREGIDA | AL34: POSTVENTA CORREGIDA | AM34: POSTVENTA CORREGIDA | AN34: POSTVENTA CORREGIDA
B35: 39 | C35: Estado de Muro | E35: TIENE POSTVENTA | F35: POSTVENTA CORREGIDA | G35: POSTVENTA CORREGIDA | H35: TIENE POSTVENTA | I35: POSTVENTA CORREGIDA | J35: POSTVENTA CORREGIDA | K35: POSTVENTA CORREGIDA | L35: POSTVENTA CORREGIDA | M35: POSTVENTA CORREGIDA | N35: POSTVENTA CORREGIDA | O35: POSTVENTA CORREGIDA | P35: POSTVENTA CORREGIDA | Q35: POSTVENTA CORREGIDA | R35: POSTVENTA CORREGIDA | S35: POSTVENTA CORREGIDA | T35: TIENE POSTVENTA | U35: TIENE POSTVENTA | V35: POSTVENTA CORREGIDA | W35: POSTVENTA CORREGIDA | X35: POSTVENTA CORREGIDA | Y35: POSTVENTA CORREGIDA | Z35: TIENE POSTVENTA | AA35: POSTVENTA CORREGIDA | AB35: POSTVENTA CORREGIDA | AC35: POSTVENTA CORREGIDA | AD35: POSTVENTA CORREGIDA | AE35: POSTVENTA CORREGIDA | AF35: TIENE POSTVENTA | AG35: POSTVENTA CORREGIDA | AH35: POSTVENTA CORREGIDA | AI35: POSTVENTA CORREGIDA | AJ35: POSTVENTA CORREGIDA | AK35: POSTVENTA CORREGIDA | AL35: POSTVENTA CORREGIDA | AM35: POSTVENTA CORREGIDA | AN35: POSTVENTA CORREGIDA
B36: 40 | C36: Piso | E36: TIENE POSTVENTA | F36: POSTVENTA CORREGIDA | G36: POSTVENTA CORREGIDA | H36: TIENE POSTVENTA | I36: POSTVENTA CORREGIDA | J36: POSTVENTA CORREGIDA | K36: POSTVENTA CORREGIDA | L36: POSTVENTA CORREGIDA | M36: POSTVENTA CORREGIDA | N36: POSTVENTA CORREGIDA | O36: POSTVENTA CORREGIDA | P36: POSTVENTA CORREGIDA | Q36: POSTVENTA CORREGIDA | R36: POSTVENTA CORREGIDA | S36: POSTVENTA CORREGIDA | T36: POSTVENTA CORREGIDA | U36: POSTVENTA CORREGIDA | V36: POSTVENTA CORREGIDA | W36: TIENE POSTVENTA | X36: POSTVENTA CORREGIDA | Y36: POSTVENTA CORREGIDA | Z36: POSTVENTA CORREGIDA | AA36: POSTVENTA CORREGIDA | AB36: POSTVENTA CORREGIDA | AC36: POSTVENTA CORREGIDA | AD36: POSTVENTA CORREGIDA | AE36: TIENE POSTVENTA | AF36: POSTVENTA CORREGIDA | AG36: POSTVENTA CORREGIDA | AH36: TIENE POSTVENTA | AI36: POSTVENTA CORREGIDA | AJ36: POSTVENTA CORREGIDA | AK36: POSTVENTA CORREGIDA | AL36: POSTVENTA CORREGIDA | AM36: POSTVENTA CORREGIDA | AN36: POSTVENTA CORREGIDA
B37: 41 | C37: Guardaescobas | E37: TIENE POSTVENTA | F37: POSTVENTA CORREGIDA | G37: POSTVENTA CORREGIDA | H37: TIENE POSTVENTA | I37: POSTVENTA CORREGIDA | J37: POSTVENTA CORREGIDA | K37: POSTVENTA CORREGIDA | L37: POSTVENTA CORREGIDA | M37: POSTVENTA CORREGIDA | N37: POSTVENTA CORREGIDA | O37: POSTVENTA CORREGIDA | P37: POSTVENTA CORREGIDA | Q37: POSTVENTA CORREGIDA | R37: POSTVENTA CORREGIDA | S37: POSTVENTA CORREGIDA | T37: POSTVENTA CORREGIDA | U37: POSTVENTA CORREGIDA | V37: POSTVENTA CORREGIDA | W37: POSTVENTA CORREGIDA | X37: POSTVENTA CORREGIDA | Y37: POSTVENTA CORREGIDA | Z37: POSTVENTA CORREGIDA | AA37: POSTVENTA CORREGIDA | AB37: POSTVENTA CORREGIDA | AC37: POSTVENTA CORREGIDA | AD37: POSTVENTA CORREGIDA | AE37: POSTVENTA CORREGIDA | AF37: POSTVENTA CORREGIDA | AG37: POSTVENTA CORREGIDA | AH37: POSTVENTA CORREGIDA | AI37: POSTVENTA CORREGIDA | AJ37: POSTVENTA CORREGIDA | AK37: POSTVENTA CORREGIDA | AL37: POSTVENTA CORREGIDA | AM37: POSTVENTA CORREGIDA | AN37: POSTVENTA CORREGIDA
B38: 42 | C38: Cielorasos | E38: TIENE POSTVENTA | F38: POSTVENTA CORREGIDA | G38: POSTVENTA CORREGIDA | H38: TIENE POSTVENTA | I38: POSTVENTA CORREGIDA | J38: POSTVENTA CORREGIDA | K38: POSTVENTA CORREGIDA | L38: POSTVENTA CORREGIDA | M38: POSTVENTA CORREGIDA | N38: POSTVENTA CORREGIDA | O38: POSTVENTA CORREGIDA | P38: POSTVENTA CORREGIDA | Q38: POSTVENTA CORREGIDA | R38: POSTVENTA CORREGIDA | S38: POSTVENTA CORREGIDA | T38: POSTVENTA CORREGIDA | U38: POSTVENTA CORREGIDA | V38: POSTVENTA CORREGIDA | W38: TIENE POSTVENTA | X38: POSTVENTA CORREGIDA | Y38: POSTVENTA CORREGIDA | Z38: POSTVENTA CORREGIDA | AA38: POSTVENTA CORREGIDA | AB38: POSTVENTA CORREGIDA | AC38: POSTVENTA CORREGIDA | AD38: TIENE POSTVENTA | AE38: POSTVENTA CORREGIDA | AF38: POSTVENTA CORREGIDA | AG38: POSTVENTA CORREGIDA | AH38: POSTVENTA CORREGIDA | AI38: POSTVENTA CORREGIDA | AJ38: POSTVENTA CORREGIDA | AK38: POSTVENTA CORREGIDA | AL38: POSTVENTA CORREGIDA | AM38: POSTVENTA CORREGIDA | AN38: POSTVENTA CORREGIDA
B39: 43 | C39: Tapavalvulas | E39: TIENE POSTVENTA | F39: POSTVENTA CORREGIDA | G39: POSTVENTA CORREGIDA | H39: TIENE POSTVENTA | I39: POSTVENTA CORREGIDA | J39: POSTVENTA CORREGIDA | K39: POSTVENTA CORREGIDA | L39: POSTVENTA CORREGIDA | M39: POSTVENTA CORREGIDA | N39: POSTVENTA CORREGIDA | O39: POSTVENTA CORREGIDA | P39: POSTVENTA CORREGIDA | Q39: POSTVENTA CORREGIDA | R39: POSTVENTA CORREGIDA | S39: POSTVENTA CORREGIDA | T39: POSTVENTA CORREGIDA | U39: POSTVENTA CORREGIDA | V39: POSTVENTA CORREGIDA | W39: POSTVENTA CORREGIDA | X39: POSTVENTA CORREGIDA | Y39: POSTVENTA CORREGIDA | Z39: POSTVENTA CORREGIDA | AA39: POSTVENTA CORREGIDA | AB39: POSTVENTA CORREGIDA | AC39: POSTVENTA CORREGIDA | AD39: POSTVENTA CORREGIDA | AE39: POSTVENTA CORREGIDA | AF39: POSTVENTA CORREGIDA | AG39: POSTVENTA CORREGIDA | AH39: POSTVENTA CORREGIDA | AI39: POSTVENTA CORREGIDA | AJ39: POSTVENTA CORREGIDA | AK39: POSTVENTA CORREGIDA | AL39: POSTVENTA CORREGIDA | AM39: POSTVENTA CORREGIDA | AN39: POSTVENTA CORREGIDA
A40: ZONA LABORES | B40: =+B39+1 -> 44 | C40: Luces | E40: TIENE POSTVENTA | F40: POSTVENTA CORREGIDA | G40: POSTVENTA CORREGIDA | H40: TIENE POSTVENTA | I40: POSTVENTA CORREGIDA | J40: POSTVENTA CORREGIDA | K40: POSTVENTA CORREGIDA | L40: POSTVENTA CORREGIDA | M40: POSTVENTA CORREGIDA | N40: POSTVENTA CORREGIDA | O40: POSTVENTA CORREGIDA | P40: POSTVENTA CORREGIDA | Q40: POSTVENTA CORREGIDA | R40: POSTVENTA CORREGIDA | S40: POSTVENTA CORREGIDA | T40: POSTVENTA CORREGIDA | U40: POSTVENTA CORREGIDA | V40: POSTVENTA CORREGIDA | W40: POSTVENTA CORREGIDA | X40: POSTVENTA CORREGIDA | Y40: POSTVENTA CORREGIDA | Z40: POSTVENTA CORREGIDA | AA40: POSTVENTA CORREGIDA | AB40: POSTVENTA CORREGIDA | AC40: POSTVENTA CORREGIDA | AD40: POSTVENTA CORREGIDA | AE40: POSTVENTA CORREGIDA | AF40: POSTVENTA CORREGIDA | AG40: POSTVENTA CORREGIDA | AH40: POSTVENTA CORREGIDA | AI40: POSTVENTA CORREGIDA | AJ40: POSTVENTA CORREGIDA | AK40: POSTVENTA CORREGIDA | AL40: POSTVENTA CORREGIDA | AM40: POSTVENTA CORREGIDA | AN40: POSTVENTA CORREGIDA
B41: =+B40+1 -> 45 | C41: Switches | E41: TIENE POSTVENTA | F41: POSTVENTA CORREGIDA | G41: POSTVENTA CORREGIDA | H41: TIENE POSTVENTA | I41: POSTVENTA CORREGIDA | J41: POSTVENTA CORREGIDA | K41: POSTVENTA CORREGIDA | L41: POSTVENTA CORREGIDA | M41: POSTVENTA CORREGIDA | N41: POSTVENTA CORREGIDA | O41: POSTVENTA CORREGIDA | P41: POSTVENTA CORREGIDA | Q41: POSTVENTA CORREGIDA | R41: POSTVENTA CORREGIDA | S41: POSTVENTA CORREGIDA | T41: POSTVENTA CORREGIDA | U41: POSTVENTA CORREGIDA | V41: POSTVENTA CORREGIDA | W41: POSTVENTA CORREGIDA | X41: POSTVENTA CORREGIDA | Y41: POSTVENTA CORREGIDA | Z41: POSTVENTA CORREGIDA | AA41: POSTVENTA CORREGIDA | AB41: POSTVENTA CORREGIDA | AC41: POSTVENTA CORREGIDA | AD41: POSTVENTA CORREGIDA | AE41: POSTVENTA CORREGIDA | AF41: POSTVENTA CORREGIDA | AG41: POSTVENTA CORREGIDA | AH41: POSTVENTA CORREGIDA | AI41: POSTVENTA CORREGIDA | AJ41: POSTVENTA CORREGIDA | AK41: POSTVENTA CORREGIDA | AL41: POSTVENTA CORREGIDA | AM41: POSTVENTA CORREGIDA | AN41: POSTVENTA CORREGIDA
...

Sheet OBSERVACIONES
B4: Item | C4: DETALLES | D4: CASA #02 | E4: CASA #03 | F4: CASA #4 | G4: CASA #05 | H4: CASA #07 | I4: CASA #11 | J4: CASA #12 | K4: CASA #14 | L4: CASA #15 | M4: CASA #17 | N4: CASA #18 | O4: CASA #19 | P4: CASA #21 | Q4: CASA #22 | R4: CASA #23 | S4: CASA #24 | T4: CASA #25 | U4: CASA #26 | V4: CASA #27 | W4: CASA #28 | X4: CASA #29 | Y4: CASA #30 | Z4: CASA #31 | AA4: CASA #32 | AB4: CASA #33 | AC4: CASA #35 | AD4: CASA #36 | AE4: CASA #37 | AF4: CASA #38 | AG4: CASA #40 | AH4: CASA #42 | AI4: CASA #43 | AJ4: CASA #44 | AK4: CASA #45 | AL4: CASA #46 | AM4: CASA #47
A5: SALA COMEDOR | B5: 1 | C5: Puerta en madera acceso p/pal | D5: NO ENTREGADO | E5: OK | F5: OK | G5: NO ENTREGADO | H5: OK | I5: OK | J5: OK | K5: OK | L5: OK | M5: DETALLE CAMBIO | N5: OK | O5: OK | P5: DETALLE FIJADO | Q5: DETALLE CAMBIO | R5: OK | S5: OK | T5: OK | U5: OK | V5: OK | W5: OK | X5: OK | Y5: OK | Z5: OK | AA5: OK | AB5: OK | AC5: OK | AD5: DETALLE FIJADO | AE5: OK | AF5: OK | AG5: DETALLAR PUERTA | AH5: OK | AI5: OK | AJ5: OK | AK5: OK | AL5: OK | AM5: DETALLE CAMBIO
B6: 2 | C6: Cerradura Puerta Principal con llaves | D6: NO ENTREGADO | E6: OK | F6: OK | G6: NO ENTREGADO | H6: OK | I6: OK | J6: OK | K6: OK | L6: OK | M6: OK | N6: OK | O6: OK | P6: OK | Q6: OK | R6: OK | S6: OK | T6: OK | U6: OK | V6: OK | W6: OK | X6: OK | Y6: OK | Z6: OK | AA6: OK | AB6: OK | AC6: OK | AD6: OK | AE6: OK | AF6: OK | AG6: OK | AH6: OK | AI6: OK | AJ6: OK | AK6: OK | AL6: OK | AM6: OK
B7: 3 | C7: Tope de puerta | D7: NO ENTREGADO | E7: OK | F7: OK | G7: NO ENTREGADO | H7: OK | I7: OK | J7: OK | K7: OK | L7: OK | M7: OK | N7: OK | O7: OK | P7: OK | Q7: OK | R7: OK | S7: OK | T7: OK | U7: OK | V7: OK | W7: OK | X7: OK | Y7: OK | Z7: OK | AA7: OK | AB7: OK | AC7: OK | AD7: OK | AE7: OK | AF7: OK | AG7: OK | AH7: OK | AI7: OK | AJ7: OK | AK7: OK | AL7: OK | AM7: OK
B8: 4 | C8: Timbre | D8: NO ENTREGADO | E8: OK | F8: OK | G8: NO ENTREGADO | H8: OK | I8: OK | J8: OK | K8: OK | L8: OK | M8: OK | N8: OK | O8: OK | P8: OK | Q8: OK | R8: OK | S8: OK | T8: OK | U8: OK | V8: OK | W8: OK | X8: OK | Y8: OK | Z8: OK | AA8: OK | AB8: OK | AC8: OK | AD8: OK | AE8: OK | AF8: OK | AG8: OK | AH8: OK | AI8: OK | AJ8: OK | AK8: OK | AL8: OK | AM8: OK
B9: 5 | C9: Luces | D9: NO ENTREGADO | E9: OK | F9: OK | G9: NO ENTREGADO | H9: OK | I9: OK | J9: OK | K9: OK | L9: OK | M9: OK | N9: OK | O9: OK | P9: OK | Q9: OK | R9: OK | S9: OK | T9: OK | U9: OK | V9: OK | W9: OK | X9: OK | Y9: OK | Z9: OK | AA9: OK | AB9: OK | AC9: OK | AD9: OK | AE9: OK | AF9: OK | AG9: OK | AH9: OK | AI9: OK | AJ9: OK | AK9: OK | AL9: OK | AM9: OK
B10: 6 | C10: Tomas | D10: NO ENTREGADO | E10: OK | F10: OK | G10: NO ENTREGADO | H10: OK | I10: OK | J10: OK | K10: OK | L10: OK | M10: OK | N10: OK | O10: OK | P10: OK | Q10: OK | R10: OK | S10: OK | T10: OK | U10: OK | V10: OK | W10: OK | X10: OK | Y10: OK | Z10: OK | AA10: OK | AB10: OK | AC10: OK | AD10: OK | AE10: OK | AF10: OK | AG10: OK | AH10: OK | AI10: OK | AJ10: OK | AK10: OK | AL10: OK | AM10: OK
B11: 7 | C11: Switches | D11: NO ENTREGADO | E11: OK | F11: OK | G11: NO ENTREGADO | H11: OK | I11: OK | J11: OK | K11: OK | L11: OK | M11: OK | N11: OK | O11: OK | P11: OK | Q11: OK | R11: OK | S11: OK | T11: OK | U11: OK | V11: OK | W11: OK | X11: OK | Y11: OK | Z11: OK | AA11: OK | AB11: OK | AC11: OK | AD11: OK | AE11: OK | AF11: OK | AG11: OK | AH11: OK | AI11: OK | AJ11: OK | AK11: OK | AL11: OK | AM11: OK
B12: 8 | C12: Cableado de Citofono | D12: NO ENTREGADO | E12: OK | F12: OK | G12: NO ENTREGADO | H12: OK | I12: OK | J12: OK | K12: OK | L12: OK | M12: OK | N12: OK | O12: OK | P12: OK | Q12: OK | R12: OK | S12: OK | T12: OK | U12: OK | V12: OK | W12: OK | X12: OK | Y12: OK | Z12: OK | AA12: OK | AB12: OK | AC12: OK | AD12: OK | AE12: OK | AF12: OK | AG12: OK | AH12: OK | AI12: OK | AJ12: OK | AK12: OK | AL12: OK | AM12: OK
B13: 9 | C13: Punto de Voz y datos/tv | D13: NO ENTREGADO | E13: OK | F13: OK | G13: NO ENTREGADO | H13: OK | I13: OK | J13: OK | K13: OK | L13: OK | M13: OK | N13: OK | O13: OK | P13: OK | Q13: OK | R13: OK | S13: OK | T13: OK | U13: OK | V13: OK | W13: OK | X13: OK | Y13: OK | Z13: OK | AA13: OK | AB13: OK | AC13: OK | AD13: OK | AE13: OK | AF13: OK | AG13: OK | AH13: OK | AI13: OK | AJ13: OK | AK13: OK | AL13: OK | AM13: OK
B14: 10 | C14: Tablero Electrico | D14: NO ENTREGADO | E14: OK | F14: OK | G14: NO ENTREGADO | H14: OK | I14: OK | J14: OK | K14: OK | L14: OK | M14: OK | N14: OK | O14: OK | P14: OK | Q14: OK | R14: OK | S14: OK | T14: OK | U14: OK | V14: OK | W14: OK | X14: OK | Y14: OK | Z14: OK | AA14: OK | AB14: OK | AC14: OK | AD14: OK | AE14: OK | AF14: OK | AG14: DETALLE TORNILLOS | AH14: OK | AI14: OK | AJ14: OK | AK14: OK | AL14: OK | AM14: OK
B15: 11 | C15: Cuñas | D15: NO ENTREGADO | E15: OK | F15: OK | G15: NO ENTREGADO | H15: OK | I15: OK | J15: OK | K15: OK | L15: OK | M15: OK | N15: OK | O15: OK | P15: OK | Q15: OK | R15: OK | S15: OK | T15: OK | U15: OK | V15: OK | W15: OK | X15: OK | Y15: OK | Z15: OK | AA15: OK | AB15: OK | AC15: OK | AD15: OK | AE15: OK | AF15: OK | AG15: OK | AH15: OK | AI15: OK | AJ15: OK | AK15: OK | AL15: OK | AM15: OK
B16: 12 | C16: Puertaventana Corrediza | D16: NO ENTREGADO | E16: OK | F16: OK | G16: NO ENTREGADO | H16: OK | I16: OK | J16: OK | K16: OK | L16: OK | M16: OK | N16: OK | O16: OK | P16: OK | Q16: OK | R16: OK | S16: OK | T16: OK | U16: OK | V16: OK | W16: OK | X16: OK | Y16: OK | Z16: OK | AA16: DETALLE FIJAADO | AB16: OK | AC16: OK | AD16: OK | AE16: OK | AF16: OK | AG16: OK | AH16: OK | AI16: OK | AJ16: OK | AK16: OK | AL16: OK | AM16: OK
B17: 13 | C17: Ventanas fijas | D17: NO ENTREGADO | E17: OK | F17: OK | G17: NO ENTREGADO | H17: OK | I17: OK | J17: OK | K17: OK | L17: OK | M17: OK | N17: OK | O17: OK | P17: OK | Q17: DETALLE CAMBIO | R17: OK | S17: OK | T17: OK | U17: OK | V17: OK | W17: OK | X17: OK | Y17: OK | Z17: OK | AA17: OK | AB17: OK | AC17: OK | AD17: OK | AE17: OK | AF17: OK | AG17: OK | AH17: OK | AI17: OK | AJ17: OK | AK17: OK | AL17: OK | AM17: OK
... B23: 19 | C23: Muros | D23: NO ENTREGADO | E23: OK | F23: OK | G23: NO ENTREGADO | H23: OK | I23: OK | J23: OK | K23: DETALLE PINTURA ESTUCO | L23: OK | M23: OK | N23: OK | O23: OK | P23: DETALLES MURO EXTERIOR | Q23: OK | R23: OK | S23: DETALLE HUMEDAD | T23: DETALLE HUMEDAD | U23: DETALLE PINTURA Y ESTUCO | V23: DETALLE PINTURA Y ESTUCO | W23: DETALLE PINTURA | X23: DETALLE PINTURA | Y23: OK | Z23: OK | AA23: OK | AB23: OK | AC23: OK | AD23: OK | AE23: DETALLE PINTURA | AF23: OK | AG23: OK | AH23: DETALLE PINTURA | AI23: OK | AJ23: DETALLE PINTURAS | AK23: OK | AL23: OK | AM23: OK
A24: COCINA | B24: 20 | C24: Luces | D24: NO ENTREGADO | E24: OK | F24: OK | G24: NO ENTREGADO | H24: OK | I24: OK | J24: OK | K24: OK | L24: OK | M24: OK | N24: OK | O24: OK | P24: OK | Q24: OK | R24: OK | S24: OK | T24: OK | U24: OK | V24: OK | W24: OK | X24: OK | Y24: OK | Z24: OK | AA24: OK | AB24: OK | AC24: OK | AD24: OK | AE24: OK | AF24: OK | AG24: OK | AH24: OK | AI24: OK | AJ24: OK | AK24: OK | AL24: OK | AM24: OK
B25: 21 | C25: Switches | D25: NO ENTREGADO | E25: OK | F25: OK | G25: NO ENTREGADO | H25: OK | I25: OK | J25: OK | K25: OK | L25: OK | M25: OK | N25: OK | O25: OK | P25: OK | Q25: OK | R25: OK | S25: OK | T25: OK | U25: OK | V25: OK | W25: OK | X25: OK | Y25: OK | Z25: OK | AA25: OK | AB25: OK | AC25: OK | AD25: OK | AE25: OK | AF25: OK | AG25: OK | AH25: OK | AI25: OK | AJ25: OK | AK25: OK | AL25: OK | AM25: OK
B26: 22 | C26: Extractor | D26: NO ENTREGADO | E26: OK | F26: OK | G26: NO ENTREGADO | H26: OK | I26: OK | J26: OK | K26: OK | L26: OK | M26: OK | N26: OK | O26: OK | P26: OK | Q26: OK | R26: OK | S26: OK | T26: OK | U26: OK | V26: OK | W26: OK | X26: OK | Y26: OK | Z26: OK | AA26: OK | AB26: OK | AC26: OK | AD26: OK | AE26: OK | AF26: OK | AG26: OK | AH26: OK | AI26: OK | AJ26: OK | AK26: OK | AL26: OK | AM26: OK
B27: 23 | C27: Griferias | D27: NO ENTREGADO | E27: OK | F27: OK | G27: NO ENTREGADO | H27: OK | I27: OK | J27: OK | K27: OK | L27: OK | M27: OK | N27: OK | O27: OK | P27: OK | Q27: OK | R27: OK | S27: OK | T27: OK | U27: OK | V27: OK | W27: OK | X27: OK | Y27: OK | Z27: OK | AA27: OK | AB27: OK | AC27: OK | AD27: OK | AE27: OK | AF27: OK | AG27: OK | AH27: OK | AI27: OK | AJ27: OK | AK27: OK | AL27: DETALLE CAMBIO | AM27: OK
B28: 24 | C28: Lavaplatos | D28: NO ENTREGADO | E28: OK | F28: OK | G28: NO ENTREGADO | H28: OK | I28: OK | J28: OK | K28: OK | L28: OK | M28: OK | N28: OK | O28: OK | P28: OK | Q28: OK | R28: OK | S28: OK | T28: OK | U28: OK | V28: OK | W28: OK | X28: OK | Y28: OK | Z28: OK | AA28: OK | AB28: OK | AC28: OK | AD28: OK | AE28: OK | AF28: OK | AG28: DETALLE SILICONA Y CONEXIÓN | AH28: OK | AI28: OK | AJ28: OK | AK28: OK | AL28: OK | AM28: OK
B29: 25 | C29: mesón | D29: NO ENTREGADO | E29: OK | F29: OK | G29: NO ENTREGADO | H29: OK | I29: OK | J29: OK | K29: OK | L29: OK | M29: OK | N29: OK | O29: OK | P29: OK | Q29: OK | R29: OK | S29: OK | T29: OK | U29: OK | V29: OK | W29: OK | X29: OK | Y29: OK | Z29: OK | AA29: OK | AB29: OK | AC29: OK | AD29: OK | AE29: OK | AF29: OK | AG29: OK | AH29: OK | AI29: OK | AJ29: OK | AK29: OK | AL29: OK | AM29: OK
B30: 26 | C30: salpicadero | D30: NO ENTREGADO | E30: OK | F30: OK | G30: NO ENTREGADO | H30: OK | I30: OK | J30: OK | K30: OK | L30: OK | M30: OK | N30: OK | O30: OK | P30: OK | Q30: OK | R30: OK | S30: OK | T30: OK | U30: OK | V30: DETALLE LIMPIEZA | W30: OK | X30: OK | Y30: OK | Z30: OK | AA30: OK | AB30: OK | AC30: OK | AD30: OK | AE30: OK | AF30: OK | AG30: OK | AH30: OK | AI30: OK | AJ30: OK | AK30: OK | AL30: OK | AM30: OK
B31: 27 | C31: mueble inferior | D31: NO ENTREGADO | E31: OK | F31: OK | G31: NO ENTREGADO | H31: OK | I31: OK | J31: OK | K31: OK | L31: OK | M31: OK | N31: DETALLE PUERTAS | O31: OK | P31: OK | Q31: OK | R31: OK | S31: OK | T31: OK | U31: OK | V31: OK | W31: OK | X31: OK | Y31: OK | Z31: OK | AA31: DETALLE PUERTAS | AB31: OK | AC31: OK | AD31: OK | AE31: OK | AF31: OK | AG31: DETALLE PUERTAS | AH31: OK | AI31: DETALLE PUERTAS | AJ31: OK | AK31: OK | AL31: OK | AM31: OK
B32: 28 | C32: mueble superior | D32: NO ENTREGADO | E32: OK | F32: OK | G32: NO ENTREGADO | H32: OK | I32: OK | J32: OK | K32: OK | L32: OK | M32: OK | N32: DETALLE PUERTAS | O32: OK | P32: DETALLES PUERTAS | Q32: OK | R32: OK | S32: OK | T32: OK | U32: OK | V32: DETALLE PUERTAS | W32: OK | X32: OK | Y32: OK | Z32: OK | AA32: OK | AB32: OK | AC32: OK | AD32: OK | AE32: OK | AF32: OK | AG32: OK | AH32: OK | AI32: OK | AJ32: OK | AK32: OK | AL32: OK | AM32: OK
B33: 29 | C33: Enchape | D33: NO ENTREGADO | E33: OK | F33: OK | G33: NO ENTREGADO | H33: OK | I33: OK | J33: OK | K33: OK | L33: OK | M33: OK | N33: OK | O33: OK | P33: OK | Q33: OK | R33: OK | S33: OK | T33: OK | U33: OK | V33: OK | W33: OK | X33: OK | Y33: OK | Z33: OK | AA33: OK | AB33: OK | AC33: OK | AD33: OK | AE33: OK | AF33: OK | AG33: OK | AH33: OK | AI33: OK | AJ33: OK | AK33: OK | AL33: OK | AM33: OK
B34: 30 | C34: Estado de Muro | D34: NO ENTREGADO | E34: OK | F34: OK | G34: NO ENTREGADO | H34: OK | I34: OK | J34: OK | K34: OK | L34: OK | M34: OK | N34: OK | O34: OK | P34: OK | Q34: OK | R34: OK | S34: DETALLE HUMEDAD | T34: DETALLE HUMEDAD | U34: OK | V34: OK | W34: OK | X34: OK | Y34: DETALLE PINTURA | Z34: OK | AA34: OK | AB34: OK | AC34: OK | AD34: OK | AE34: DETALLE PINTURA | AF34: OK | AG34: OK | AH34: OK | AI34: OK | AJ34: OK | AK34: OK | AL34: OK | AM34: OK
B35: 31 | C35: Piso | D35: NO ENTREGADO | E35: OK | F35: OK | G35: NO ENTREGADO | H35: OK | I35: OK | J35: OK | K35: OK | L35: OK | M35: OK | N35: OK | O35: OK | P35: OK | Q35: OK | R35: OK | S35: OK | T35: OK | U35: OK | V35: DETALLE BALDOSAS | W35: OK | X35: OK | Y35: OK | Z35: OK | AA35: OK | AB35: OK | AC35: OK | AD35: DETALLE CERAMICA | AE35: OK | AF35: OK | AG35: DETALLE JUNTAS | AH35: OK | AI35: OK | AJ35: OK | AK35: OK | AL35: OK | AM35: OK
B36: 32 | C36: Guardaescobas | D36: NO ENTREGADO | E36: OK | F36: OK | G36: NO ENTREGADO | H36: OK | I36: OK | J36: OK | K36: OK | L36: OK | M36: OK | N36: OK | O36: OK | P36: OK | Q36: OK | R36: OK | S36: OK | T36: OK | U36: OK | V36: OK | W36: OK | X36: OK | Y36: OK | Z36: OK | AA36: OK | AB36: OK | AC36: OK | AD36: OK | AE36: OK | AF36: OK | AG36: OK | AH36: OK | AI36: OK | AJ36: OK | AK36: OK | AL36: OK | AM36: OK
... B38: 34 | C38: Tapavalvulas | D38: NO ENTREGADO | E38: OK | F38: OK | G38: NO ENTREGADO | H38: OK | I38: OK | J38: OK | K38: OK | L38: OK | M38: OK | N38: OK | O38: OK | P38: OK | Q38: OK | R38: OK | S38: OK | T38: OK | U38: OK | V38: OK | W38: OK | X38: OK | Y38: OK | Z38: OK | AA38: OK | AB38: OK | AC38: OK | AD38: OK | AE38: OK | AF38: OK | AG38: OK | AH38: OK | AI38: OK | AJ38: OK | AK38: OK | AL38: OK | AM38: OK
A39: ZONA LABORES | B39: 35 | C39: Luces | D39: NO ENTREGADO | E39: OK | F39: OK | G39: NO ENTREGADO | H39: OK | I39: OK | J39: OK | K39: OK | L39: OK | M39: OK | N39: OK | O39: OK | P39: OK | Q39: OK | R39: OK | S39: OK | T39: OK | U39: OK | V39: OK | W39: OK | X39: OK | Y39: OK | Z39: OK | AA39: OK | AB39: OK | AC39: OK | AD39: OK | AE39: OK | AF39: OK | AG39: OK | AH39: OK | AI39: OK | AJ39: OK | AK39: OK | AL39: OK | AM39: OK
B40: 36 | C40: Switches | D40: NO ENTREGADO | E40: OK | F40: OK | G40: NO ENTREGADO | H40: OK | I40: OK | J40: OK | K40: OK | L40: OK | M40: OK | N40: OK | O40: OK | P40: OK | Q40: OK | R40: OK | S40: OK | T40: OK | U40: OK | V40: OK | W40: OK | X40: OK | Y40: OK | Z40: OK | AA40: OK | AB40: OK | AC40: OK | AD40: OK | AE40: OK | AF40: OK | AG40: OK | AH40: OK | AI40: OK | AJ40: OK | AK40: OK | AL40: OK | AM40: OK
B41: 37 | C41: Griferias | D41: NO ENTREGADO | E41: OK | F41: OK | G41: NO ENTREGADO | H41: OK | I41: OK | J41: OK | K41: OK | L41: OK | M41: OK | N41: OK | O41: OK | P41: OK | Q41: OK | R41: OK | S41: OK | T41: OK | U41: OK | V41: OK | W41: OK | X41: OK | Y41: OK | Z41: OK | AA41: OK | AB41: OK | AC41: OK | AD41: DETALLE ARREGLO | AE41: OK | AF41: OK | AG41: OK | AH41: OK | AI41: OK | AJ41: OK | AK41: OK | AL41: OK | AM41: OK
B42: 38 | C42: Lavadero | D42: NO ENTREGADO | E42: OK | F42: OK | G42: NO ENTREGADO | H42: OK | I42: OK | J42: OK | K42: OK | L42: OK | M42: OK | N42: DETALLE DE LLAVE | O42: OK | P42: OK | Q42: OK | R42: OK | S42: OK | T42: OK | U42: OK | V42: OK | W42: OK | X42: OK | Y42: OK | Z42: OK | AA42: OK | AB42: OK | AC42: OK | AD42: OK | AE42: OK | AF42: OK | AG42: DETALLE BOQUILLA | AH42: OK | AI42: OK | AJ42: OK | AK42: OK | AL42: OK | AM42: OK
B43: 39 | C43: Enchape | D43: NO ENTREGADO | E43: OK | F43: OK | G43: NO ENTREGADO | H43: OK | I43: OK | J43: OK | K43: OK | L43: OK | M43: OK | N43: OK | O43: OK | P43: OK | Q43: OK | R43: OK | S43: OK | T43: OK | U43: OK | V43: OK | W43: OK | X43: OK | Y43: OK | Z43: OK | AA43: OK | AB43: OK | AC43: OK | AD43: OK | AE43: OK | AF43: OK | AG43: OK | AH43: OK | AI43: OK | AJ43: OK | AK43: OK | AL43: OK | AM43: OK
B44: 40 | C44: Estado de Muro | D44: NO ENTREGADO | E44: OK | F44: OK | G44: NO ENTREGADO | H44: OK | I44: OK | J44: OK | K44: OK | L44: OK | M44: OK | N44: OK | O44: OK | P44: OK | Q44: OK | R44: OK | S44: DETALLE HUMEDAD | T44: DETALLE HUMEDAD | U44: OK | V44: DETALLE PINTURA Y ESTUCO | W44: OK | X44: OK | Y44: DETALLE PINTURA | Z44: OK | AA44: OK | AB44: OK | AC44: OK | AD44: OK | AE44: DETALLE PINTURA | AF44: OK | AG44: OK | AH44: OK | AI44: OK | AJ44: OK | AK44: OK | AL44: OK | AM44: DETALLE PINTURA
B45: 41 | C45: Piso | D45: NO ENTREGADO | E45: OK | F45: OK | G45: NO ENTREGADO | H45: DETALLE BALDOSA | I45: OK | J45: OK | K45: OK | L45: OK | M45: OK | N45: OK | O45: OK | P45: OK | Q45: OK | R45: OK | S45: OK | T45: OK | U45: OK | V45: OK | W45: OK | X45: OK | Y45: OK | Z45: OK | AA45: DETALLE BALDOSAS | AB45: OK | AC45: OK | AD45: OK | AE45: OK | AF45: OK | AG45: DETALLE BOQUILLA | AH45: OK | AI45: OK | AJ45: OK | AK45: OK | AL45: OK | AM45: OK
B46: 42 | C46: Guardaescobas | D46: NO ENTREGADO | E46: OK | F46: OK | G46: NO ENTREGADO | H46: OK | I46: OK | J46: OK | K46: OK | L46: OK | M46: OK | N46: OK | O46: OK | P46: OK | Q46: OK | R46: OK | S46: OK | T46: OK | U46: OK | V46: OK | W46: OK | X46: OK | Y46: OK | Z46: OK | AA46: OK | AB46: OK | AC46: OK | AD46: OK | AE46: OK | AF46: OK | AG46: OK | AH46: OK | AI46: OK | AJ46: OK | AK46: OK | AL46: OK | AM46: OK
B47: 43 | C47: Cielorasos | D47: NO ENTREGADO | E47: OK | F47: OK | G47: NO ENTREGADO | H47: OK | I47: OK | J47: OK | K47: OK | L47: OK | M47: OK | N47: OK | O47: OK | P47: OK | Q47: OK | R47: OK | S47: OK | T47: OK | U47: OK | V47: DETALLE FILTRACION | W47: OK | X47: OK | Y47: OK | Z47: OK | AA47: OK | AB47: OK | AC47: OK | AD47: OK | AE47: OK | AF47: OK | AG47: OK | AH47: OK | AI47: OK | AJ47: OK | AK47: OK | AL47: OK | AM47: OK
B48: 44 | C48: Tapavalvulas | D48: NO ENTREGADO | E48: OK | F48: OK | G48: NO ENTREGADO | H48: OK | I48: OK | J48: OK | K48: OK | L48: OK | M48: OK | N48: OK | O48: OK | P48: OK | Q48: OK | R48: OK | S48: OK | T48: OK | U48: OK | V48: OK | W48: OK | X48: OK | Y48: OK | Z48: OK | AA48: OK | AB48: OK | AC48: OK | AD48: OK | AE48: OK | AF48: OK | AG48: OK | AH48: OK | AI48: OK | AJ48: OK | AK48: OK | AL48: OK | AM48: OK
A49: BAÑO SOCIAL | B49: 45 | C49: Puerta | D49: NO ENTREGADO | E49: OK | F49: OK | G49: NO ENTREGADO | H49: OK | I49: OK | J49: OK | K49: OK | L49: OK | M49: OK | N49: OK | O49: DETALLE CAMBIO | P49: OK | Q49: OK | R49: OK | S49: OK | T49: DETALLE MARCO | U49: OK | V49: OK | W49: OK | X49: OK | Y49: OK | Z49: OK | AA49: OK | AB49: OK | AC49: OK | AD49: OK | AE49: OK | AF49: OK | AG49: OK | AH49: OK | AI49: OK | AJ49: OK | AK49: OK | AL49: OK | AM49: OK
...

Sheet |

Sheet CODICIONALES
A1: NO TIENE POSTVENTA
A2: OK ESTADO DE POSTVENTAS: POSTVENTA CORREGIDA | B2: NO ENTREGADO ESTADO DE POSTVENTAS: TIENE POSTVENTA | C2: NO ENTREGADO ESTADO DE POSTVENTAS: POSTVENTA CORREGIDA

Sheet RESUMEN
R2: ESTADO DE POSTVENTAS:
AN3: SEMANA 22 - 27 SEPTIEMBRE | AQ3: SEMANA 29 SEPTIEMBRE - 03 OCTUBRE | AT3: SEMANA 06 - 11 OCTUBRE
B4: Item | C4: DETALLES | D4: CASA #02 | E4: CASA #03 | F4: CASA #4 | G4: CASA #05 | H4: CASA #07 | I4: CASA #11 | J4: CASA #12 | K4: CASA #14 | L4: CASA #15 | M4: CASA #17 | N4: CASA #18 | O4: CASA #19 | P4: CASA #21 | Q4: CASA #22 | R4: CASA #23 | S4: CASA #24 | T4: CASA #25 | U4: CASA #26 | V4: CASA #27 | W4: CASA #28 | X4: CASA #29 | Y4: CASA #30 | Z4: CASA #31 | AA4: CASA #32 | AB4: CASA #33 | AC4: CASA #35 | AD4: CASA #36 | AE4: CASA #37 | AF4: CASA #38 | AG4: CASA #40 | AH4: CASA #42 | AI4: CASA #43 | AJ4: CASA #44 | AK4: CASA #45 | AL4: CASA #46 | AM4: CASA #47 | AN4: CANTIDAD DE CASA CON PROBLEMAS | AO4: CANTIDAD DE CASA CORREGIDAS | AP4: NO TIENEN DETALLES | AQ4: CANTIDAD DE CASA CON PROBLEMAS | AR4: CANTIDAD DE CASA CORREGIDAS | AS4: NO TIENEN DETALLES | AT4: CANTIDAD DE CASA CON PROBLEMAS | AU4: CANTIDAD DE CASA CORREGIDAS | AV4: NO TIENEN DETALLES
